<?xml version="1.0" encoding="utf-8"?>
<!-- This URDF was automatically created by SolidWorks to URDF Exporter! Originally created by Stephen Brawner (brawner@gmail.com) 
     Commit Version: 1.6.0-4-g7f85cfe  Build Version: 1.6.7995.38578
     For more information, please see http://wiki.ros.org/sw_urdf_exporter -->
<robot
  name="oscar_new">
    <xacro:property name="chassis_length" value="0.335"/>
    <xacro:property name="chassis_width" value="0.265"/>
    <xacro:property name="chassis_height" value="0.138"/>
  <link
    name="base_link">
    <inertial>
      <origin
        xyz="0.00196170680937007 -0.0868228015469567 -0.0309340370914814"
        rpy="0 0 0" />
      <mass
        value="0.458411450979246" />
      <inertia
        ixx="0.000542871589384656"
        ixy="1.69749191833194E-07"
        ixz="9.16830524623752E-08"
        iyy="0.000657663684621469"
        iyz="-3.00802775983815E-06"
        izz="0.00108671668484761" />
    </inertial>
    <visual>
      <origin
        xyz="0 0 0"
        rpy="0 0 0" />
            <geometry>
                <box size="${chassis_length} ${chassis_width} ${chassis_height}"/>
            </geometry>
      <material
        name="">
        <color
          rgba="1 1 1 1" />
      </material>
    </visual>
    <collision>
      <origin
        xyz="0 0 0"
        rpy="0 0 0" />
            <geometry>
                <box size="${chassis_length} ${chassis_width} ${chassis_height}"/>
            </geometry>
    </collision>
  </link>
  <link
    name="Left_wheel_link">
    <inertial>
      <origin
        xyz="-0.00784940612576868 4.28642898509662E-05 -9.31058257115994E-06"
        rpy="0 0 0" />
      <mass
        value="0.0274335863022573" />
      <inertia
        ixx="1.13862377406955E-05"
        ixy="-4.63211244042856E-15"
        ixz="9.35749928836235E-15"
        iyy="6.00789413976309E-06"
        iyz="-1.82633067451514E-08"
        izz="6.02049780409006E-06" />
    </inertial>
    <visual>
      <origin
        xyz="0 0 0"
        rpy="0 0 0" />
      <geometry>
        <mesh
          filename="package://oscar_new/meshes/Left_wheel_link.STL" />
      </geometry>
      <material
        name="">
        <color
          rgba="1 1 1 1" />
      </material>
    </visual>
    <collision>
      <origin
        xyz="0 0 0"
        rpy="0 0 0" />
      <geometry>
        <mesh
          filename="package://oscar_new/meshes/Left_wheel_link.STL" />
      </geometry>
    </collision>
  </link>
  <joint
    name="Left_wheel_link_joint"
    type="continuous">
    <origin
      xyz="0.0586 -0.08 -0.035"
      rpy="2.7498 0 3.1416" />
    <parent
      link="base_link" />
    <child
      link="Left_wheel_link" />
    <axis
      xyz="1 0 0" />
  </joint>
  <link
    name="Right_wheel_link">
    <inertial>
      <origin
        xyz="-0.00784940612576874 4.28642898509385E-05 -9.31058257162831E-06"
        rpy="0 0 0" />
      <mass
        value="0.0274335863022572" />
      <inertia
        ixx="1.13862377406954E-05"
        ixy="-4.63212894995761E-15"
        ixz="9.3575734507046E-15"
        iyy="6.00789413976302E-06"
        iyz="-1.82633067450594E-08"
        izz="6.02049780409007E-06" />
    </inertial>
    <visual>
      <origin
        xyz="0 0 0"
        rpy="0 0 0" />
      <geometry>
        <mesh
          filename="package://oscar_new/meshes/Right_wheel_link.STL" />
      </geometry>
      <material
        name="">
        <color
          rgba="1 1 1 1" />
      </material>
    </visual>
    <collision>
      <origin
        xyz="0 0 0"
        rpy="0 0 0" />
      <geometry>
        <mesh
          filename="package://oscar_new/meshes/Right_wheel_link.STL" />
      </geometry>
    </collision>
  </link>
  <joint
    name="Right_wheel_link_joint"
    type="continuous">
    <origin
      xyz="-0.0586 -0.08 -0.035"
      rpy="1.5708 0 0" />
    <parent
      link="base_link" />
    <child
      link="Right_wheel_link" />
    <axis
      xyz="1 0 0" />
  </joint>
  <link
    name="Link_pair_1">
    <inertial>
      <origin
        xyz="0.0122273760193206 -3.21860593732737E-14 0.0079914509294892"
        rpy="0 0 0" />
      <mass
        value="0.00369780273035827" />
      <inertia
        ixx="6.11514536437229E-08"
        ixy="-5.820653179875E-24"
        ixz="2.01266652952978E-24"
        iyy="6.25046675936164E-07"
        iyz="-7.7711533483172E-25"
        izz="6.70790618203394E-07" />
    </inertial>
    <visual>
      <origin
        xyz="0 0 0"
        rpy="0 0 0" />
      <geometry>
        <mesh
          filename="package://oscar_new/meshes/Link_pair_1.STL" />
      </geometry>
      <material
        name="">
        <color
          rgba="1 1 1 1" />
      </material>
    </visual>
    <collision>
      <origin
        xyz="0 0 0"
        rpy="0 0 0" />
      <geometry>
        <mesh
          filename="package://oscar_new/meshes/Link_pair_1.STL" />
      </geometry>
    </collision>
  </link>
  <joint
    name="Link_pair_1_joint"
    type="continuous">
    <origin
      xyz="0.087 -0.0695 -0.018"
      rpy="1.5708 0 0" />
    <parent
      link="base_link" />
    <child
      link="Link_pair_1" />
    <axis
      xyz="0 0 1" />
  </joint>
  <link
    name="big_triangle_1">
    <inertial>
      <origin
        xyz="0.0195755407568848 -0.00278501208050816 0.0180107799944266"
        rpy="0 0 0" />
      <mass
        value="0.074547880950281" />
      <inertia
        ixx="5.43833714550981E-05"
        ixy="-1.64485303519001E-06"
        ixz="1.46443358252426E-06"
        iyy="6.94150724784236E-05"
        iyz="-7.5546027497944E-07"
        izz="2.41737178555845E-05" />
    </inertial>
    <visual>
      <origin
        xyz="0 0 0"
        rpy="0 0 0" />
      <geometry>
        <mesh
          filename="package://oscar_new/meshes/big_triangle_1.STL" />
      </geometry>
      <material
        name="">
        <color
          rgba="1 1 1 1" />
      </material>
    </visual>
    <collision>
      <origin
        xyz="0 0 0"
        rpy="0 0 0" />
      <geometry>
        <mesh
          filename="package://oscar_new/meshes/big_triangle_1.STL" />
      </geometry>
    </collision>
  </link>
  <joint
    name="big_triangle_1_joint"
    type="continuous">
    <origin
      xyz="0.0365000000000118 0 0"
      rpy="0.0087266462599717 0 0" />
    <parent
      link="Link_pair_1" />
    <child
      link="big_triangle_1" />
    <axis
      xyz="0 0.00872653549837413 0.999961923064171" />
  </joint>
  <link
    name="link_1">
    <inertial>
      <origin
        xyz="0.00925000000000004 -3.56659146660832E-15 -6.93889390390723E-17"
        rpy="0 0 0" />
      <mass
        value="0.000418829254091884" />
      <inertia
        ixx="1.72374656454096E-09"
        ixy="2.13344257577636E-22"
        ixz="2.0524418948972E-23"
        iyy="2.05758913679062E-08"
        iyz="7.09745245672708E-25"
        izz="2.16713940513094E-08" />
    </inertial>
    <visual>
      <origin
        xyz="0 0 0"
        rpy="0 0 0" />
      <geometry>
        <mesh
          filename="package://oscar_new/meshes/link_1.STL" />
      </geometry>
      <material
        name="">
        <color
          rgba="0.858823529411765 0.858823529411765 0.858823529411765 0.1" />
      </material>
    </visual>
    <collision>
      <origin
        xyz="0 0 0"
        rpy="0 0 0" />
      <geometry>
        <mesh
          filename="package://oscar_new/meshes/link_1.STL" />
      </geometry>
    </collision>
  </link>
  <joint
    name="link_1_joint"
    type="continuous">
    <origin
      xyz="0.051256 -0.01171 0.033266"
      rpy="-0.012341 -0.78536 0.0087263" />
    <parent
      link="big_triangle_1" />
    <child
      link="link_1" />
    <axis
      xyz="0 0 1" />
  </joint>
  <link
    name="big_non_actuated_triangle_mirror">
    <inertial>
      <origin
        xyz="0.030919243545911 0.00878668880203192 -0.0148475592469524"
        rpy="0 0 0" />
      <mass
        value="0.0721297540054504" />
      <inertia
        ixx="5.39632726368139E-05"
        ixy="1.56283388931883E-06"
        ixz="-1.44322942163294E-06"
        iyy="6.91067908994078E-05"
        iyz="5.02154368175076E-08"
        izz="2.3503289928344E-05" />
    </inertial>
    <visual>
      <origin
        xyz="0 0 0"
        rpy="0 0 0" />
      <geometry>
        <mesh
          filename="package://oscar_new/meshes/big_non_actuated_triangle_mirror.STL" />
      </geometry>
      <material
        name="">
        <color
          rgba="1 1 1 1" />
      </material>
    </visual>
    <collision>
      <origin
        xyz="0 0 0"
        rpy="0 0 0" />
      <geometry>
        <mesh
          filename="package://oscar_new/meshes/big_non_actuated_triangle_mirror.STL" />
      </geometry>
    </collision>
  </link>
  <joint
    name="big_non_actuated_triangle_mirror_joint"
    type="continuous">
    <origin
      xyz="0.0185000000000003 0 0"
      rpy="-0.0174516313869211 -0.785283940562994 0.0123396187386001" />
    <parent
      link="link_1" />
    <child
      link="big_non_actuated_triangle_mirror" />
    <axis
      xyz="0.707026008833154 -0.0123409498970772 0.707079856727016" />
  </joint>
  <link
    name="Link_5">
    <inertial>
      <origin
        xyz="0.0182500000000126 -2.2610868039008E-11 0.00150000000000006"
        rpy="0 0 0" />
      <mass
        value="0.000742829254091884" />
      <inertia
        ixx="2.93874656454096E-09"
        ixy="-1.39940107034916E-19"
        ixz="2.71430278997525E-22"
        iyy="1.08501881755647E-07"
        iyz="-2.71872076740319E-17"
        izz="1.1032638443905E-07" />
    </inertial>
    <visual>
      <origin
        xyz="0 0 0"
        rpy="0 0 0" />
      <geometry>
        <mesh
          filename="package://oscar_new/meshes/Link_5.STL" />
      </geometry>
      <material
        name="">
        <color
          rgba="0.858823529411765 0.858823529411765 0.858823529411765 0.1" />
      </material>
    </visual>
    <collision>
      <origin
        xyz="0 0 0"
        rpy="0 0 0" />
      <geometry>
        <mesh
          filename="package://oscar_new/meshes/Link_5.STL" />
      </geometry>
    </collision>
  </link>
  <joint
    name="Link_5_joint"
    type="continuous">
    <origin
      xyz="0.0513601265840201 0.0117364716817143 -0.0210572480975253"
      rpy="-3.13286602223098 0 -0.00872664625996893" />
    <parent
      link="big_non_actuated_triangle_mirror" />
    <child
      link="Link_5" />
    <axis
      xyz="0 0 1" />
  </joint>
  <link
    name="Link_pair_2">
    <inertial>
      <origin
        xyz="0.0122273760193164 -1.88078719265405E-14 0.00250854907051047"
        rpy="0 0 0" />
      <mass
        value="0.00369780273035827" />
      <inertia
        ixx="6.11514536437228E-08"
        ixy="8.67254029541453E-19"
        ixz="6.28274244545554E-23"
        iyy="6.25046675936164E-07"
        iyz="-4.99214669239447E-24"
        izz="6.70790618203394E-07" />
    </inertial>
    <visual>
      <origin
        xyz="0 0 0"
        rpy="0 0 0" />
      <geometry>
        <mesh
          filename="package://oscar_new/meshes/Link_pair_2.STL" />
      </geometry>
      <material
        name="">
        <color
          rgba="1 1 1 1" />
      </material>
    </visual>
    <collision>
      <origin
        xyz="0 0 0"
        rpy="0 0 0" />
      <geometry>
        <mesh
          filename="package://oscar_new/meshes/Link_pair_2.STL" />
      </geometry>
    </collision>
  </link>
  <joint
    name="Link_pair_2_joint"
    type="continuous">
    <origin
      xyz="0 -0.167 -0.018"
      rpy="-1.5708 0 -1.5708" />
    <parent
      link="base_link" />
    <child
      link="Link_pair_2" />
    <axis
      xyz="0 0 1" />
  </joint>
  <link
    name="big_triangle_middle">
    <inertial>
      <origin
        xyz="0.0223421497135244 0.00326069237224212 0.0026854172102378"
        rpy="0 0 0" />
      <mass
        value="0.0834635434624063" />
      <inertia
        ixx="4.56673953012276E-05"
        ixy="-6.35604825028362E-08"
        ixz="2.01812979626431E-06"
        iyy="2.18500355396937E-05"
        iyz="2.26274897050134E-21"
        izz="5.43856488817236E-05" />
    </inertial>
    <visual>
      <origin
        xyz="0 0 0"
        rpy="0 0 0" />
      <geometry>
        <mesh
          filename="package://oscar_new/meshes/big_triangle_middle.STL" />
      </geometry>
      <material
        name="">
        <color
          rgba="1 1 1 1" />
      </material>
    </visual>
    <collision>
      <origin
        xyz="0 0 0"
        rpy="0 0 0" />
      <geometry>
        <mesh
          filename="package://oscar_new/meshes/big_triangle_middle.STL" />
      </geometry>
    </collision>
  </link>
  <joint
    name="big_triangle_middle_joint"
    type="continuous">
    <origin
      xyz="0.0365 0 0"
      rpy="-1.5707963267949 0 0" />
    <parent
      link="Link_pair_2" />
    <child
      link="big_triangle_middle" />
    <axis
      xyz="0 1 0" />
  </joint>
  <link
    name="Link_2">
    <inertial>
      <origin
        xyz="0.0092499999999997 1.20042864537595E-15 2.77555756156289E-17"
        rpy="0 0 0" />
      <mass
        value="0.000418829254091885" />
      <inertia
        ixx="1.72374656454096E-09"
        ixy="-1.07562054460996E-23"
        ixz="3.32423208669748E-23"
        iyy="2.05758913679062E-08"
        iyz="5.24370415022561E-25"
        izz="2.16713940513094E-08" />
    </inertial>
    <visual>
      <origin
        xyz="0 0 0"
        rpy="0 0 0" />
      <geometry>
        <mesh
          filename="package://oscar_new/meshes/Link_2.STL" />
      </geometry>
      <material
        name="">
        <color
          rgba="0.858823529411765 0.858823529411765 0.858823529411765 0.1" />
      </material>
    </visual>
    <collision>
      <origin
        xyz="0 0 0"
        rpy="0 0 0" />
      <geometry>
        <mesh
          filename="package://oscar_new/meshes/Link_2.STL" />
      </geometry>
    </collision>
  </link>
  <joint
    name="Link_2_joint"
    type="continuous">
    <origin
      xyz="0.0512557522110201 -0.0226627723370287 0.0120000000000011"
      rpy="-1.5707963267949 0 -0.785398163397446" />
    <parent
      link="big_triangle_middle" />
    <child
      link="Link_2" />
    <axis
      xyz="0 0 1" />
  </joint>
  <link
    name="small_triangle_1">
    <inertial>
      <origin
        xyz="-0.0328199233156058 -0.00838171459412368 0.0100577286903399"
        rpy="0 0 0" />
      <mass
        value="0.0478134415054504" />
      <inertia
        ixx="1.16931866407475E-05"
        ixy="-3.1676773406174E-06"
        ixz="-1.41779823992198E-06"
        iyy="1.22757737145985E-05"
        iyz="3.6055996039486E-07"
        izz="1.56922706277985E-05" />
    </inertial>
    <visual>
      <origin
        xyz="0 0 0"
        rpy="0 0 0" />
      <geometry>
        <mesh
          filename="package://oscar_new/meshes/small_triangle_1.STL" />
      </geometry>
      <material
        name="">
        <color
          rgba="1 1 1 1" />
      </material>
    </visual>
    <collision>
      <origin
        xyz="0 0 0"
        rpy="0 0 0" />
      <geometry>
        <mesh
          filename="package://oscar_new/meshes/small_triangle_1.STL" />
      </geometry>
    </collision>
  </link>
  <joint
    name="small_triangle_1_joint"
    type="continuous">
    <origin
      xyz="0.0184999999999997 0 0"
      rpy="1.5707963267949 -0.785398163397451 3.14159265358979" />
    <parent
      link="Link_2" />
    <child
      link="small_triangle_1" />
    <axis
      xyz="0.707106781186548 0.707106781186547 0" />
  </joint>
  <link
    name="Link_6">
    <inertial>
      <origin
        xyz="0.0182499999999999 5.59413626533001E-14 0.0015"
        rpy="0 0 0" />
      <mass
        value="0.000742829254091884" />
      <inertia
        ixx="2.93874656454096E-09"
        ixy="1.21906504358734E-24"
        ixz="-1.3436838192585E-24"
        iyy="1.08501881755647E-07"
        iyz="7.10258518665798E-27"
        izz="1.10326384439051E-07" />
    </inertial>
    <visual>
      <origin
        xyz="0 0 0"
        rpy="0 0 0" />
      <geometry>
        <mesh
          filename="package://oscar_new/meshes/Link_6.STL" />
      </geometry>
      <material
        name="">
        <color
          rgba="0.858823529411765 0.858823529411765 0.858823529411765 0.1" />
      </material>
    </visual>
    <collision>
      <origin
        xyz="0 0 0"
        rpy="0 0 0" />
      <geometry>
        <mesh
          filename="package://oscar_new/meshes/Link_6.STL" />
      </geometry>
    </collision>
  </link>
  <joint
    name="Link_6_joint"
    type="continuous">
    <origin
      xyz="-0.0512557522110201 0.00616277233702894 0.011999999999944"
      rpy="1.5707963267949 0 3.14159265358979" />
    <parent
      link="small_triangle_1" />
    <child
      link="Link_6" />
    <axis
      xyz="0 0 1" />
  </joint>
  <link
    name="rectangle_mirror_link ">
    <inertial>
      <origin
        xyz="0.0253000582270056 0.0755932370668164 0.0112636448534606"
        rpy="0 0 0" />
      <mass
        value="0.164023892383727" />
      <inertia
        ixx="0.000289386199645965"
        ixy="-3.43537232454044E-06"
        ixz="-1.71295548901096E-06"
        iyy="9.46049698257021E-05"
        iyz="1.74658343347169E-06"
        izz="0.000341456068141042" />
    </inertial>
    <visual>
      <origin
        xyz="0 0 0"
        rpy="0 0 0" />
      <geometry>
        <mesh
          filename="package://oscar_new/meshes/rectangle_mirror_link .STL" />
      </geometry>
      <material
        name="">
        <color
          rgba="1 1 1 1" />
      </material>
    </visual>
    <collision>
      <origin
        xyz="0 0 0"
        rpy="0 0 0" />
      <geometry>
        <mesh
          filename="package://oscar_new/meshes/rectangle_mirror_link .STL" />
      </geometry>
    </collision>
  </link>
  <joint
    name="rectangle_mirror_link_joint"
    type="continuous">
    <origin
      xyz="0.0365000000000011 0 0"
      rpy="1.5707963267949 1.5707963267949 0" />
    <parent
      link="Link_6" />
    <child
      link="rectangle_mirror_link " />
    <axis
      xyz="1 0 0" />
  </joint>
  <link
    name="Link_3">
    <inertial>
      <origin
        xyz="-0.00924999999999998 0 0.01425"
        rpy="0 0 0" />
      <mass
        value="0.000418829254091883" />
      <inertia
        ixx="1.72374656454096E-09"
        ixy="-3.44375965656593E-24"
        ixz="-1.3648480107125E-23"
        iyy="2.05758913679062E-08"
        iyz="-9.86326119353998E-26"
        izz="2.16713940513093E-08" />
    </inertial>
    <visual>
      <origin
        xyz="0 0 0"
        rpy="0 0 0" />
      <geometry>
        <mesh
          filename="package://oscar_new/meshes/Link_3.STL" />
      </geometry>
      <material
        name="">
        <color
          rgba="0.858823529411765 0.858823529411765 0.858823529411765 0.1" />
      </material>
    </visual>
    <collision>
      <origin
        xyz="0 0 0"
        rpy="0 0 0" />
      <geometry>
        <mesh
          filename="package://oscar_new/meshes/Link_3.STL" />
      </geometry>
    </collision>
  </link>
  <joint
    name="Link_3_joint"
    type="continuous">
    <origin
      xyz="0.0411794805791117 0.0327390439689375 0.012"
      rpy="-1.5707963267949 0 -2.35619449019234" />
    <parent
      link="big_triangle_middle" />
    <child
      link="Link_3" />
    <axis
      xyz="0 0 1" />
  </joint>
  <link
    name="small_triangle_mirror_1">
    <inertial>
      <origin
        xyz="-0.0227436516836974 0.00169455703778471 -0.0100577286903399"
        rpy="0 0 0" />
      <mass
        value="0.0478134415054504" />
      <inertia
        ixx="1.16931866407475E-05"
        ixy="-3.1676773406174E-06"
        ixz="1.41779823992197E-06"
        iyy="1.22757737145985E-05"
        iyz="-3.60559960394858E-07"
        izz="1.56922706277985E-05" />
    </inertial>
    <visual>
      <origin
        xyz="0 0 0"
        rpy="0 0 0" />
      <geometry>
        <mesh
          filename="package://oscar_new/meshes/small_triangle_mirror_1.STL" />
      </geometry>
      <material
        name="">
        <color
          rgba="1 1 1 1" />
      </material>
    </visual>
    <collision>
      <origin
        xyz="0 0 0"
        rpy="0 0 0" />
      <geometry>
        <mesh
          filename="package://oscar_new/meshes/small_triangle_mirror_1.STL" />
      </geometry>
    </collision>
  </link>
  <joint
    name="small_triangle_mirror_1_joint"
    type="continuous">
    <origin
      xyz="-0.0185000000000001 0 0"
      rpy="1.5707963267949 -0.785398163397448 0" />
    <parent
      link="Link_3" />
    <child
      link="small_triangle_mirror_1" />
    <axis
      xyz="0.707106781186548 0.707106781186547 0" />
  </joint>
  <link
    name="Link_7">
    <inertial>
      <origin
        xyz="-0.0182499999999994 1.1221926166094E-13 0.00149999999999956"
        rpy="0 0 0" />
      <mass
        value="0.000742829254091884" />
      <inertia
        ixx="2.93874656454096E-09"
        ixy="-7.56512651365417E-25"
        ixz="-9.39787035785344E-25"
        iyy="1.08501881755647E-07"
        iyz="7.10258518665798E-27"
        izz="1.10326384439051E-07" />
    </inertial>
    <visual>
      <origin
        xyz="0 0 0"
        rpy="0 0 0" />
      <geometry>
        <mesh
          filename="package://oscar_new/meshes/Link_7.STL" />
      </geometry>
      <material
        name="">
        <color
          rgba="0.858823529411765 0.858823529411765 0.858823529411765 0.1" />
      </material>
    </visual>
    <collision>
      <origin
        xyz="0 0 0"
        rpy="0 0 0" />
      <geometry>
        <mesh
          filename="package://oscar_new/meshes/Link_7.STL" />
      </geometry>
    </collision>
  </link>
  <joint
    name="Link_7_joint"
    type="continuous">
    <origin
      xyz="-0.0411794805791123 0.0162390439689377 -0.0119999999998877"
      rpy="-1.5707963267949 0 0" />
    <parent
      link="small_triangle_mirror_1" />
    <child
      link="Link_7" />
    <axis
      xyz="0 0 1" />
  </joint>
  <link
    name="rectangle_link">
    <inertial>
      <origin
        xyz="0.0253000482387464 -0.0755932420609482 0.0112636448534604"
        rpy="0 0 0" />
      <mass
        value="0.164023892383727" />
      <inertia
        ixx="0.000289386199645965"
        ixy="3.43537232446941E-06"
        ixz="-1.71294995482485E-06"
        iyy="9.46049698257021E-05"
        iyz="-1.74658343347196E-06"
        izz="0.000341456068141042" />
    </inertial>
    <visual>
      <origin
        xyz="0 0 0"
        rpy="0 0 0" />
      <geometry>
        <mesh
          filename="package://oscar_new/meshes/rectangle_link.STL" />
      </geometry>
      <material
        name="">
        <color
          rgba="1 1 1 1" />
      </material>
    </visual>
    <collision>
      <origin
        xyz="0 0 0"
        rpy="0 0 0" />
      <geometry>
        <mesh
          filename="package://oscar_new/meshes/rectangle_link.STL" />
      </geometry>
    </collision>
  </link>
  <joint
    name="rectangle_link_joint"
    type="continuous">
    <origin
      xyz="-0.0364999999999998 0 0"
      rpy="1.5707963267949 1.5707963267949 0" />
    <parent
      link="Link_7" />
    <child
      link="rectangle_link" />
    <axis
      xyz="1 0 0" />
  </joint>
  <link
    name="Link_pair_3">
    <inertial>
      <origin
        xyz="0.0122273760193164 -1.87905246917808E-14 0.00799145092948914"
        rpy="0 0 0" />
      <mass
        value="0.00369780273035826" />
      <inertia
        ixx="6.11514536437226E-08"
        ixy="8.6665940999138E-19"
        ixz="1.37808747279263E-21"
        iyy="6.25046675936162E-07"
        iyz="3.81628572207125E-24"
        izz="6.70790618203392E-07" />
    </inertial>
    <visual>
      <origin
        xyz="0 0 0"
        rpy="0 0 0" />
      <geometry>
        <mesh
          filename="package://oscar_new/meshes/Link_pair_3.STL" />
      </geometry>
      <material
        name="">
        <color
          rgba="1 1 1 1" />
      </material>
    </visual>
    <collision>
      <origin
        xyz="0 0 0"
        rpy="0 0 0" />
      <geometry>
        <mesh
          filename="package://oscar_new/meshes/Link_pair_3.STL" />
      </geometry>
    </collision>
  </link>
  <joint
    name="Link_pair_3_joint"
    type="continuous">
    <origin
      xyz="-0.0870000000000001 -0.0694999999999998 -0.018"
      rpy="-1.5707963267949 0 3.14159265358979" />
    <parent
      link="base_link" />
    <child
      link="Link_pair_3" />
    <axis
      xyz="0 0 1" />
  </joint>
  <link
    name="big_triangle_mirror_1">
    <inertial>
      <origin
        xyz="-0.0196018382100973 -0.00292797471366951 0.0179594317026352"
        rpy="0 0 0" />
      <mass
        value="0.0745478809502811" />
      <inertia
        ixx="5.44136654321586E-05"
        ixy="1.80118553221312E-06"
        ixz="-1.43514860815113E-06"
        iyy="6.9397363779311E-05"
        iyz="4.6975848217259E-08"
        izz="2.41611325776369E-05" />
    </inertial>
    <visual>
      <origin
        xyz="0 0 0"
        rpy="0 0 0" />
      <geometry>
        <mesh
          filename="package://oscar_new/meshes/big_triangle_mirror_1.STL" />
      </geometry>
      <material
        name="">
        <color
          rgba="1 1 1 1" />
      </material>
    </visual>
    <collision>
      <origin
        xyz="0 0 0"
        rpy="0 0 0" />
      <geometry>
        <mesh
          filename="package://oscar_new/meshes/big_triangle_mirror_1.STL" />
      </geometry>
    </collision>
  </link>
  <joint
    name="big_triangle_mirror_1_joint"
    type="continuous">
    <origin
      xyz="0.0365 0 0"
      rpy="-0.00872631399289004 7.61524218754158E-05 -3.1328663395969" />
    <parent
      link="Link_pair_3" />
    <child
      link="big_triangle_mirror_1" />
    <axis
      xyz="7.61524218037561E-05 0.00872620321864122 -0.999961923064171" />
  </joint>
  <link
    name="Link_4">
    <inertial>
      <origin
        xyz="0.00924999999999979 -5.61044266600419E-14 -0.0142499999999998"
        rpy="0 0 0" />
      <mass
        value="0.000418829254091883" />
      <inertia
        ixx="1.72374656454095E-09"
        ixy="-1.45897428116002E-23"
        ixz="1.70606001339062E-24"
        iyy="2.05758913679061E-08"
        iyz="2.40999549744314E-25"
        izz="2.16713940513093E-08" />
    </inertial>
    <visual>
      <origin
        xyz="0 0 0"
        rpy="0 0 0" />
      <geometry>
        <mesh
          filename="package://oscar_new/meshes/Link_4.STL" />
      </geometry>
      <material
        name="">
        <color
          rgba="0.858823529411765 0.858823529411765 0.858823529411765 0.1" />
      </material>
    </visual>
    <collision>
      <origin
        xyz="0 0 0"
        rpy="0 0 0" />
      <geometry>
        <mesh
          filename="package://oscar_new/meshes/Link_4.STL" />
      </geometry>
    </collision>
  </link>
  <joint
    name="Link_4_joint"
    type="continuous">
    <origin
      xyz="-0.0412859197872106 -0.0120170446565131 0.0431326791326552"
      rpy="-0.0123410282316681 -0.785360087186511 3.14159232132272" />
    <parent
      link="big_triangle_mirror_1" />
    <child
      link="Link_4" />
    <axis
      xyz="0 0 1" />
  </joint>
  <link
    name="big_non_actuated_triangle_1">
    <inertial>
      <origin
        xyz="-0.0207651172522063 0.00870773622874539 -0.0250792378465225"
        rpy="0 0 0" />
      <mass
        value="0.0721297540054504" />
      <inertia
        ixx="5.39371506401738E-05"
        ixy="-1.4050380646756E-06"
        ixz="1.46835760801126E-06"
        iyy="6.91203276181002E-05"
        iyz="-7.58629222720149E-07"
        izz="2.35158752062916E-05" />
    </inertial>
    <visual>
      <origin
        xyz="0 0 0"
        rpy="0 0 0" />
      <geometry>
        <mesh
          filename="package://oscar_new/meshes/big_non_actuated_triangle_1.STL" />
      </geometry>
      <material
        name="">
        <color
          rgba="1 1 1 1" />
      </material>
    </visual>
    <collision>
      <origin
        xyz="0 0 0"
        rpy="0 0 0" />
      <geometry>
        <mesh
          filename="package://oscar_new/meshes/big_non_actuated_triangle_1.STL" />
      </geometry>
    </collision>
  </link>
  <joint
    name="big_non_actuated_triangle_1_joint"
    type="continuous">
    <origin
      xyz="0.0185 0 0"
      rpy="0.00872664625996892 0.785398163397449 3.14159265358979" />
    <parent
      link="Link_4" />
    <child
      link="big_non_actuated_triangle_1" />
    <axis
      xyz="0.707106781186549 -0.00617059242716257 -0.707079856727015" />
  </joint>
  <link
    name="Link_8">
    <inertial>
      <origin
        xyz="-0.01825 5.61009572130899E-14 -0.00149999999999981"
        rpy="0 0 0" />
      <mass
        value="0.000742829254091885" />
      <inertia
        ixx="2.93874656454097E-09"
        ixy="-5.19149119511322E-23"
        ixz="-1.86933357495152E-22"
        iyy="1.08501881755647E-07"
        iyz="-1.52157858907412E-25"
        izz="1.10326384439051E-07" />
    </inertial>
    <visual>
      <origin
        xyz="0 0 0"
        rpy="0 0 0" />
      <geometry>
        <mesh
          filename="package://oscar_new/meshes/Link_8.STL" />
      </geometry>
      <material
        name="">
        <color
          rgba="0.858823529411765 0.858823529411765 0.858823529411765 0.1" />
      </material>
    </visual>
    <collision>
      <origin
        xyz="0 0 0"
        rpy="0 0 0" />
      <geometry>
        <mesh
          filename="package://oscar_new/meshes/Link_8.STL" />
      </geometry>
    </collision>
  </link>
  <joint
    name="Link_8_joint"
    type="continuous">
    <origin
      xyz="-0.0411794805791117 0.0117269344506399 -0.0313425729078451"
      rpy="-0.00872664625996892 0 0" />
    <parent
      link="big_non_actuated_triangle_1" />
    <child
      link="Link_8" />
    <axis
      xyz="0 0 1" />
  </joint>
</robot>